Traceback (most recent call last):
  File "C:\Users\prabh\anaconda3\lib\site-packages\jupyter_cache\executors\utils.py", line 51, in single_nb_execution
    executenb(
  File "C:\Users\prabh\anaconda3\lib\site-packages\nbclient\client.py", line 1204, in execute
    return NotebookClient(nb=nb, resources=resources, km=km, **kwargs).execute()
  File "C:\Users\prabh\anaconda3\lib\site-packages\nbclient\util.py", line 84, in wrapped
    return just_run(coro(*args, **kwargs))
  File "C:\Users\prabh\anaconda3\lib\site-packages\nbclient\util.py", line 62, in just_run
    return loop.run_until_complete(coro)
  File "C:\Users\prabh\anaconda3\lib\asyncio\base_events.py", line 647, in run_until_complete
    return future.result()
  File "C:\Users\prabh\anaconda3\lib\site-packages\nbclient\client.py", line 663, in async_execute
    await self.async_execute_cell(
  File "C:\Users\prabh\anaconda3\lib\site-packages\nbclient\client.py", line 965, in async_execute_cell
    await self._check_raise_for_error(cell, cell_index, exec_reply)
  File "C:\Users\prabh\anaconda3\lib\site-packages\nbclient\client.py", line 862, in _check_raise_for_error
    raise CellExecutionError.from_cell_and_msg(cell, exec_reply_content)
nbclient.exceptions.CellExecutionError: An error occurred while executing the following cell:
------------------
from jupyterquiz import display_quiz
import json
with open("L1Q.json", "r") as file:
    questions=json.load(file)
    
display_quiz(questions)
------------------

[1;31m---------------------------------------------------------------------------[0m
[1;31mModuleNotFoundError[0m                       Traceback (most recent call last)
Input [1;32mIn [5][0m, in [0;36m<cell line: 1>[1;34m()[0m
[1;32m----> 1[0m [38;5;28;01mfrom[39;00m [38;5;21;01mjupyterquiz[39;00m [38;5;28;01mimport[39;00m display_quiz
[0;32m      2[0m [38;5;28;01mimport[39;00m [38;5;21;01mjson[39;00m
[0;32m      3[0m [38;5;28;01mwith[39;00m [38;5;28mopen[39m([38;5;124m"[39m[38;5;124mL1Q.json[39m[38;5;124m"[39m, [38;5;124m"[39m[38;5;124mr[39m[38;5;124m"[39m) [38;5;28;01mas[39;00m file:

[1;31mModuleNotFoundError[0m: No module named 'jupyterquiz'
ModuleNotFoundError: No module named 'jupyterquiz'

